WARNING:tensorflow:From /Users/lbarberiscanoni/Lorenzo/Github/bubble-poppers/env/lib/python3.6/site-packages/tensorflow/python/ops/resource_variable_ops.py:435: colocate_with (from tensorflow.python.framework.ops) is deprecated and will be removed in a future version.
Instructions for updating:
Colocations handled automatically by placer.
WARNING:tensorflow:From /Users/lbarberiscanoni/Lorenzo/Github/bubble-poppers/env/lib/python3.6/site-packages/tensorflow/python/ops/math_ops.py:3066: to_int32 (from tensorflow.python.ops.math_ops) is deprecated and will be removed in a future version.
Instructions for updating:
Use tf.cast instead.
2019-12-02 14:48:59.394962: I tensorflow/core/platform/cpu_feature_guard.cc:141] Your CPU supports instructions that this TensorFlow binary was not compiled to use: AVX2 FMA
WARNING:tensorflow:From /Users/lbarberiscanoni/Lorenzo/Github/bubble-poppers/env/lib/python3.6/site-packages/tensorflow/python/training/saver.py:1266: checkpoint_exists (from tensorflow.python.training.checkpoint_management) is deprecated and will be removed in a future version.
Instructions for updating:
Use standard file APIs to check for files with this prefix.
2019-12-02 14:49:01.736129: W tensorflow/core/framework/op_kernel.cc:1401] OP_REQUIRES failed at save_restore_v2_ops.cc:184 : Not found: Key inner-optimizer.step/inner-optimizer.step/beta1_power not found in checkpoint
agent ready <tensorforce.agents.ppo_agent.PPOAgent object at 0x135cf6f28>
testing
Traceback (most recent call last):
  File "/Users/lbarberiscanoni/Lorenzo/Github/bubble-poppers/env/lib/python3.6/site-packages/tensorflow/python/client/session.py", line 1334, in _do_call
    return fn(*args)
  File "/Users/lbarberiscanoni/Lorenzo/Github/bubble-poppers/env/lib/python3.6/site-packages/tensorflow/python/client/session.py", line 1319, in _run_fn
    options, feed_dict, fetch_list, target_list, run_metadata)
  File "/Users/lbarberiscanoni/Lorenzo/Github/bubble-poppers/env/lib/python3.6/site-packages/tensorflow/python/client/session.py", line 1407, in _call_tf_sessionrun
    run_metadata)
tensorflow.python.framework.errors_impl.NotFoundError: Key inner-optimizer.step/inner-optimizer.step/beta1_power not found in checkpoint
	 [[{{node save/RestoreV2}}]]

During handling of the above exception, another exception occurred:

Traceback (most recent call last):
  File "/Users/lbarberiscanoni/Lorenzo/Github/bubble-poppers/env/lib/python3.6/site-packages/tensorflow/python/training/saver.py", line 1276, in restore
    {self.saver_def.filename_tensor_name: save_path})
  File "/Users/lbarberiscanoni/Lorenzo/Github/bubble-poppers/env/lib/python3.6/site-packages/tensorflow/python/client/session.py", line 929, in run
    run_metadata_ptr)
  File "/Users/lbarberiscanoni/Lorenzo/Github/bubble-poppers/env/lib/python3.6/site-packages/tensorflow/python/client/session.py", line 1152, in _run
    feed_dict_tensor, options, run_metadata)
  File "/Users/lbarberiscanoni/Lorenzo/Github/bubble-poppers/env/lib/python3.6/site-packages/tensorflow/python/client/session.py", line 1328, in _do_run
    run_metadata)
  File "/Users/lbarberiscanoni/Lorenzo/Github/bubble-poppers/env/lib/python3.6/site-packages/tensorflow/python/client/session.py", line 1348, in _do_call
    raise type(e)(node_def, op, message)
tensorflow.python.framework.errors_impl.NotFoundError: Key inner-optimizer.step/inner-optimizer.step/beta1_power not found in checkpoint
	 [[node save/RestoreV2 (defined at /Users/lbarberiscanoni/Lorenzo/Github/bubble-poppers/tensorforce/tensorforce/core/models/model.py:495) ]]

Caused by op 'save/RestoreV2', defined at:
  File "recommender.py", line 134, in <module>
    agent.restore(directory="saved/" + args.agent + "/" + args.contrarian)
  File "/Users/lbarberiscanoni/Lorenzo/Github/bubble-poppers/tensorforce/tensorforce/agents/agent.py", line 359, in restore
    self.model.setup()
  File "/Users/lbarberiscanoni/Lorenzo/Github/bubble-poppers/tensorforce/tensorforce/core/models/model.py", line 376, in setup
    self.setup_saver()
  File "/Users/lbarberiscanoni/Lorenzo/Github/bubble-poppers/tensorforce/tensorforce/core/models/model.py", line 495, in setup_saver
    filename=None
  File "/Users/lbarberiscanoni/Lorenzo/Github/bubble-poppers/env/lib/python3.6/site-packages/tensorflow/python/training/saver.py", line 832, in __init__
    self.build()
  File "/Users/lbarberiscanoni/Lorenzo/Github/bubble-poppers/env/lib/python3.6/site-packages/tensorflow/python/training/saver.py", line 844, in build
    self._build(self._filename, build_save=True, build_restore=True)
  File "/Users/lbarberiscanoni/Lorenzo/Github/bubble-poppers/env/lib/python3.6/site-packages/tensorflow/python/training/saver.py", line 881, in _build
    build_save=build_save, build_restore=build_restore)
  File "/Users/lbarberiscanoni/Lorenzo/Github/bubble-poppers/env/lib/python3.6/site-packages/tensorflow/python/training/saver.py", line 513, in _build_internal
    restore_sequentially, reshape)
  File "/Users/lbarberiscanoni/Lorenzo/Github/bubble-poppers/env/lib/python3.6/site-packages/tensorflow/python/training/saver.py", line 332, in _AddRestoreOps
    restore_sequentially)
  File "/Users/lbarberiscanoni/Lorenzo/Github/bubble-poppers/env/lib/python3.6/site-packages/tensorflow/python/training/saver.py", line 580, in bulk_restore
    return io_ops.restore_v2(filename_tensor, names, slices, dtypes)
  File "/Users/lbarberiscanoni/Lorenzo/Github/bubble-poppers/env/lib/python3.6/site-packages/tensorflow/python/ops/gen_io_ops.py", line 1572, in restore_v2
    name=name)
  File "/Users/lbarberiscanoni/Lorenzo/Github/bubble-poppers/env/lib/python3.6/site-packages/tensorflow/python/framework/op_def_library.py", line 788, in _apply_op_helper
    op_def=op_def)
  File "/Users/lbarberiscanoni/Lorenzo/Github/bubble-poppers/env/lib/python3.6/site-packages/tensorflow/python/util/deprecation.py", line 507, in new_func
    return func(*args, **kwargs)
  File "/Users/lbarberiscanoni/Lorenzo/Github/bubble-poppers/env/lib/python3.6/site-packages/tensorflow/python/framework/ops.py", line 3300, in create_op
    op_def=op_def)
  File "/Users/lbarberiscanoni/Lorenzo/Github/bubble-poppers/env/lib/python3.6/site-packages/tensorflow/python/framework/ops.py", line 1801, in __init__
    self._traceback = tf_stack.extract_stack()

NotFoundError (see above for traceback): Key inner-optimizer.step/inner-optimizer.step/beta1_power not found in checkpoint
	 [[node save/RestoreV2 (defined at /Users/lbarberiscanoni/Lorenzo/Github/bubble-poppers/tensorforce/tensorforce/core/models/model.py:495) ]]


During handling of the above exception, another exception occurred:

Traceback (most recent call last):
  File "/Users/lbarberiscanoni/Lorenzo/Github/bubble-poppers/env/lib/python3.6/site-packages/tensorflow/python/training/saver.py", line 1286, in restore
    names_to_keys = object_graph_key_mapping(save_path)
  File "/Users/lbarberiscanoni/Lorenzo/Github/bubble-poppers/env/lib/python3.6/site-packages/tensorflow/python/training/saver.py", line 1591, in object_graph_key_mapping
    checkpointable.OBJECT_GRAPH_PROTO_KEY)
  File "/Users/lbarberiscanoni/Lorenzo/Github/bubble-poppers/env/lib/python3.6/site-packages/tensorflow/python/pywrap_tensorflow_internal.py", line 370, in get_tensor
    status)
  File "/Users/lbarberiscanoni/Lorenzo/Github/bubble-poppers/env/lib/python3.6/site-packages/tensorflow/python/framework/errors_impl.py", line 528, in __exit__
    c_api.TF_GetCode(self.status.status))
tensorflow.python.framework.errors_impl.NotFoundError: Key _CHECKPOINTABLE_OBJECT_GRAPH not found in checkpoint

During handling of the above exception, another exception occurred:

Traceback (most recent call last):
  File "recommender.py", line 134, in <module>
    agent.restore(directory="saved/" + args.agent + "/" + args.contrarian)
  File "/Users/lbarberiscanoni/Lorenzo/Github/bubble-poppers/tensorforce/tensorforce/agents/agent.py", line 361, in restore
    self.timestep, self.episode = self.model.restore(directory=directory, filename=filename)
  File "/Users/lbarberiscanoni/Lorenzo/Github/bubble-poppers/tensorforce/tensorforce/core/models/model.py", line 1230, in restore
    self.saver.restore(sess=self.session, save_path=save_path)
  File "/Users/lbarberiscanoni/Lorenzo/Github/bubble-poppers/env/lib/python3.6/site-packages/tensorflow/python/training/saver.py", line 1292, in restore
    err, "a Variable name or other graph key that is missing")
tensorflow.python.framework.errors_impl.NotFoundError: Restoring from checkpoint failed. This is most likely due to a Variable name or other graph key that is missing from the checkpoint. Please ensure that you have not altered the graph expected based on the checkpoint. Original error:

Key inner-optimizer.step/inner-optimizer.step/beta1_power not found in checkpoint
	 [[node save/RestoreV2 (defined at /Users/lbarberiscanoni/Lorenzo/Github/bubble-poppers/tensorforce/tensorforce/core/models/model.py:495) ]]

Caused by op 'save/RestoreV2', defined at:
  File "recommender.py", line 134, in <module>
    agent.restore(directory="saved/" + args.agent + "/" + args.contrarian)
  File "/Users/lbarberiscanoni/Lorenzo/Github/bubble-poppers/tensorforce/tensorforce/agents/agent.py", line 359, in restore
    self.model.setup()
  File "/Users/lbarberiscanoni/Lorenzo/Github/bubble-poppers/tensorforce/tensorforce/core/models/model.py", line 376, in setup
    self.setup_saver()
  File "/Users/lbarberiscanoni/Lorenzo/Github/bubble-poppers/tensorforce/tensorforce/core/models/model.py", line 495, in setup_saver
    filename=None
  File "/Users/lbarberiscanoni/Lorenzo/Github/bubble-poppers/env/lib/python3.6/site-packages/tensorflow/python/training/saver.py", line 832, in __init__
    self.build()
  File "/Users/lbarberiscanoni/Lorenzo/Github/bubble-poppers/env/lib/python3.6/site-packages/tensorflow/python/training/saver.py", line 844, in build
    self._build(self._filename, build_save=True, build_restore=True)
  File "/Users/lbarberiscanoni/Lorenzo/Github/bubble-poppers/env/lib/python3.6/site-packages/tensorflow/python/training/saver.py", line 881, in _build
    build_save=build_save, build_restore=build_restore)
  File "/Users/lbarberiscanoni/Lorenzo/Github/bubble-poppers/env/lib/python3.6/site-packages/tensorflow/python/training/saver.py", line 513, in _build_internal
    restore_sequentially, reshape)
  File "/Users/lbarberiscanoni/Lorenzo/Github/bubble-poppers/env/lib/python3.6/site-packages/tensorflow/python/training/saver.py", line 332, in _AddRestoreOps
    restore_sequentially)
  File "/Users/lbarberiscanoni/Lorenzo/Github/bubble-poppers/env/lib/python3.6/site-packages/tensorflow/python/training/saver.py", line 580, in bulk_restore
    return io_ops.restore_v2(filename_tensor, names, slices, dtypes)
  File "/Users/lbarberiscanoni/Lorenzo/Github/bubble-poppers/env/lib/python3.6/site-packages/tensorflow/python/ops/gen_io_ops.py", line 1572, in restore_v2
    name=name)
  File "/Users/lbarberiscanoni/Lorenzo/Github/bubble-poppers/env/lib/python3.6/site-packages/tensorflow/python/framework/op_def_library.py", line 788, in _apply_op_helper
    op_def=op_def)
  File "/Users/lbarberiscanoni/Lorenzo/Github/bubble-poppers/env/lib/python3.6/site-packages/tensorflow/python/util/deprecation.py", line 507, in new_func
    return func(*args, **kwargs)
  File "/Users/lbarberiscanoni/Lorenzo/Github/bubble-poppers/env/lib/python3.6/site-packages/tensorflow/python/framework/ops.py", line 3300, in create_op
    op_def=op_def)
  File "/Users/lbarberiscanoni/Lorenzo/Github/bubble-poppers/env/lib/python3.6/site-packages/tensorflow/python/framework/ops.py", line 1801, in __init__
    self._traceback = tf_stack.extract_stack()

NotFoundError (see above for traceback): Restoring from checkpoint failed. This is most likely due to a Variable name or other graph key that is missing from the checkpoint. Please ensure that you have not altered the graph expected based on the checkpoint. Original error:

Key inner-optimizer.step/inner-optimizer.step/beta1_power not found in checkpoint
	 [[node save/RestoreV2 (defined at /Users/lbarberiscanoni/Lorenzo/Github/bubble-poppers/tensorforce/tensorforce/core/models/model.py:495) ]]

